<?xml version="1.0" encoding="utf-8"?>
<!-- This URDF was automatically created by SolidWorks to URDF Exporter! Originally created by Stephen Brawner (brawner@gmail.com) 
     Commit Version: 1.5.1-0-g916b5db  Build Version: 1.5.7152.31018
     For more information, please see http://wiki.ros.org/sw_urdf_exporter -->
<robot
  name="urdf_files">
  <link
    name="base_link">
    <inertial>
      <origin
        xyz="-0.000245405735387999 0.176708927673057 0.00200662816430458"
        rpy="0 0 0" />
      <mass
        value="73.1987225940831" />
      <inertia
        ixx="5.44844381853453"
        ixy="0.000530588416338094"
        ixz="0.00684956990429821"
        iyy="4.94620833738639"
        iyz="0.0418907255499782"
        izz="0.794151271490352" />
    </inertial>
    <visual>
      <origin
        xyz="0 0 0"
        rpy="0 0 0" />
      <geometry>
        <mesh
          filename="package://urdf_files/meshes/base_link.STL" />
      </geometry>
      <material
        name="">
        <color
          rgba="0.792156862745098 0.819607843137255 0.933333333333333 1" />
      </material>
    </visual>
    <collision>
      <origin
        xyz="0 0 0"
        rpy="0 0 0" />
      <geometry>
        <mesh
          filename="package://urdf_files/meshes/base_link.STL" />
      </geometry>
    </collision>
  </link>
  <link
    name="Turntable_Link">
    <inertial>
      <origin
        xyz="3.91763135820788E-09 0.205567132192906 -0.00190110285770567"
        rpy="0 0 0" />
      <mass
        value="0.227999436482662" />
      <inertia
        ixx="0.000570763969480878"
        ixy="1.48699454009952E-11"
        ixz="2.69155197840914E-12"
        iyy="0.000802639067555957"
        iyz="5.46441695495813E-08"
        izz="0.000323934062677162" />
    </inertial>
    <visual>
      <origin
        xyz="0 0 0"
        rpy="0 0 0" />
      <geometry>
        <mesh
          filename="package://urdf_files/meshes/Turntable_Link.STL" />
      </geometry>
      <material
        name="">
        <color
          rgba="0.898039215686275 0.917647058823529 0.929411764705882 1" />
      </material>
    </visual>
    <collision>
      <origin
        xyz="0 0 0"
        rpy="0 0 0" />
      <geometry>
        <mesh
          filename="package://urdf_files/meshes/Turntable_Link.STL" />
      </geometry>
    </collision>
  </link>
  <joint
    name="Turntable"
    type="continuous">
    <origin
      xyz="0.029464 -0.40799 0.059056"
      rpy="1.5708 0 3.1416" />
    <parent
      link="base_link" />
    <child
      link="Turntable_Link" />
    <axis
      xyz="0 -1 0" />
  </joint>
  <link
    name="Lower-Arm_Link">
    <inertial>
      <origin
        xyz="0.233061562897836 0.293782293719561 -9.12156950666487E-10"
        rpy="0 0 0" />
      <mass
        value="0.991682751991289" />
      <inertia
        ixx="0.0085625561640718"
        ixy="-0.0130932756356974"
        ixz="-1.51270777719062E-11"
        iyy="0.0306481453453158"
        iyz="2.88975286149604E-12"
        izz="0.0392090151653679" />
    </inertial>
    <visual>
      <origin
        xyz="0 0 0"
        rpy="0 0 0" />
      <geometry>
        <mesh
          filename="package://urdf_files/meshes/Lower-Arm_Link.STL" />
      </geometry>
      <material
        name="">
        <color
          rgba="0.898039215686275 0.917647058823529 0.929411764705882 1" />
      </material>
    </visual>
    <collision>
      <origin
        xyz="0 0 0"
        rpy="0 0 0" />
      <geometry>
        <mesh
          filename="package://urdf_files/meshes/Lower-Arm_Link.STL" />
      </geometry>
    </collision>
  </link>
  <joint
    name="Lower-Arm"
    type="continuous">
    <origin
      xyz="0 0.18949 0"
      rpy="1.5708 1.0411 1.5708" />
    <parent
      link="Turntable_Link" />
    <child
      link="Lower-Arm_Link" />
    <axis
      xyz="0 0 1" />
  </joint>
  <link
    name="Upper-Arm_Link">
    <inertial>
      <origin
        xyz="-0.389304198489268 0.236602256783372 1.62407178677659E-09"
        rpy="0 0 0" />
      <mass
        value="0.537973764882104" />
      <inertia
        ixx="0.000176359531021174"
        ixy="0.000243676618961583"
        ixz="1.37699254869698E-11"
        iyy="0.012563907734834"
        iyz="5.41325045272918E-12"
        izz="0.012739343200944" />
    </inertial>
    <visual>
      <origin
        xyz="0 0 0"
        rpy="0 0 0" />
      <geometry>
        <mesh
          filename="package://urdf_files/meshes/Upper-Arm_Link.STL" />
      </geometry>
      <material
        name="">
        <color
          rgba="0.898039215686275 0.917647058823529 0.929411764705882 1" />
      </material>
    </visual>
    <collision>
      <origin
        xyz="0 0 0"
        rpy="0 0 0" />
      <geometry>
        <mesh
          filename="package://urdf_files/meshes/Upper-Arm_Link.STL" />
      </geometry>
    </collision>
  </link>
  <joint
    name="Upper-Arm"
    type="continuous">
    <origin
      xyz="0.084492 0.14432 0"
      rpy="0 0 -2.3039" />
    <parent
      link="Lower-Arm_Link" />
    <child
      link="Upper-Arm_Link" />
    <axis
      xyz="0 0 1" />
  </joint>
  <link
    name="Scoop_Link">
    <inertial>
      <origin
        xyz="0.219598152218763 -0.182686439253031 -1.86898274634473E-11"
        rpy="0 0 0" />
      <mass
        value="0.201108630026289" />
      <inertia
        ixx="0.000208232213351491"
        ixy="-7.29191619926531E-05"
        ixz="5.39582740208427E-18"
        iyy="0.000293811680022154"
        iyz="3.03202611839885E-18"
        izz="0.000367984985857797" />
    </inertial>
    <visual>
      <origin
        xyz="0 0 0"
        rpy="0 0 0" />
      <geometry>
        <mesh
          filename="package://urdf_files/meshes/Scoop_Link.STL" />
      </geometry>
      <material
        name="">
        <color
          rgba="0.894117647058823 0.913725490196078 0.929411764705882 1" />
      </material>
    </visual>
    <collision>
      <origin
        xyz="0 0 0"
        rpy="0 0 0" />
      <geometry>
        <mesh
          filename="package://urdf_files/meshes/Scoop_Link.STL" />
      </geometry>
    </collision>
  </link>
  <joint
    name="Scoop"
    type="continuous">
    <origin
      xyz="-0.092545 -0.019096 0"
      rpy="0 0 1.9904" />
    <parent
      link="Upper-Arm_Link" />
    <child
      link="Scoop_Link" />
    <axis
      xyz="0 0 1" />
  </joint>
</robot>
